Workbook
Name a_canvas: Tabela!$AC$104:$AC$105
Name a_cetim: Tabela!$AD$104:$AD$105
Name alta_definicao: Tabela!$AD$114:$AD$118
Name canvas: Tabela!$AC$104:$AC$105
Name CC: CÁLCULO!$D$26
Name cetim: Tabela!$AD$104:$AD$105
Name dupla_densidade: Tabela!$AB$114:$AB$125
Name formula_batidas: Tabela!$AD$92
Name larg_calc: Tabela!$C$24
Name larg_real: Tabela!$C$23
Name lista_teste: Tabela!$AC$48:$AC$54
Name metros: Tabela!$M$19
Name milheiros: Tabela!$M$21
Name nadson: Tabela!$AD$95
Name nome_cortes: CÁLCULO!$D$39:$D$52
Name perc_aumento_geral: Plan2!$A$46
Name perc_ultrassonico: Plan2!$A$43
Name sarja: Tabela!$AB$104:$AB$106
Name SERGIO: Tabela!$AH$112
Name super_batidas: Tabela!$AF$104:$AF$106
Name SuperSoft: Tabela!$AE$104:$AE$107
Name tab_cortes: CÁLCULO!$E$39:$F$52
Name tab_metros: Plan2!$B$4:$E$11
Name tab_tipos: Tabela!$AN$45:$AN$52
Name tabela_fator: Plan2!$H$5:$AI$18
Name tafeta: Tabela!$AB$109:$AB$111
Name tipo: Tabela!$E$23
Name urdume: Tabela!$AQ$32:$AS$39
Name valor_total: Tabela!$S$15
Name var_largura: CÁLCULO!$B$5

Sheet Tabela
C1: =IF(R1<X3,"TABELA EXPIRADA","F U T U R A ETIQUETAS") -> TABELA EXPIRADA | R1: 45657 | T1: Pedido
AJ2: VALOR PRINCIPAL | AK2: =IF(AND(S23="CORTE ESPECIAL ",Q20="")=TRUE,"VER SEGUNDOS",( IF(AND( U17="",M19<(T11*0.85)),"VER TABELA",IF(C23=60,1.49,1)*(IF(B40=M19,CÁLCULO!H13,"GRADE ERRADA"))*(IF(U16="",1,(IF(U15="+",(1+U16%),(1-U16%)))))*(IF(S25="SIM",1.15,1))*V41)) ) -> #VALUE! | AL2: =CÁLCULO!H13 -> 251.24
C3: 15 DE JANEIRO DE 2024 | T3: QTD | X3: =TODAY() -> 45981
A4: REVENDEDOR | N4: COD | Q4: Marca | AJ4: quadro para cpf cnpj | AM4: quadro para Insc. Est e RG
A5: ENDEREÇO | N5: Nº | Q5: Bairro | AK5: CPF | AN5: Insc. Est.
A6: CIDADE | N6: UF | Q6: CEP | AK6: CNPJ | AN6: R.G.
A7: CPF | N7: Insc. Est. | U7: NFe | BK7: +
A8: E-MAIL | N8: FONE | BK8: -
K10: =IF(OR(T10="Cheque",T10="Boleto bancário"),"Consultar Serasa","Dinheiro") -> Dinheiro | Q10: FORMA PAG. | T10: a vista | V10: Campo Obrigatório
A11: EMISSÃO | C11: =(NOW()) -> 45981.404 | E11: VENDAS | K11: COD. OPER. | N11: 1 | Q11: TABELA | T11: 500
A15: Valores | C15: Milheiro | E15: =valor_total/milheiros -> 14.081016 | H15: Metro | K15: =valor_total/metros -> 0.56324064 | M15: Unid. | O15: =IF(larg_calc=60,1.49,1)*(CÁLCULO!A16)*(IF(U16="",1,(IF(U15="+",(1+U16%),(1-U16%))))*(IF(S25="sim",perc_ultrassonico,1)))*V41*perc_aumento_geral -> 0.014081016 | Q15: Total | S15: =O15*M20 -> 281.62032 | U15: +
AE16: =(IF(S25="sim",perc_ultrassonico,1)) -> 1 | AJ16: Quadro para repetição e SIMPLES | AM16: Forma de pagamento
A17: - - - - - - - - - - - - - - - - - - - - - - - - - - - - - - - - - - - - - - - - - - - - - - - - - - - - - - - - - - - - - - - - - - - - - - - - - - - - - - - - - - | U17: . | AK17: SIM | AN17: a vista
C18: Pedido | F18: QT | G18: Repetição | K18: Quantidades | Q18: Opcionais | AK18: NÃO | AN18: Deposito em conta
C19: 01futb | F19: =U3 -> 0 | K19: Metros | M19: 500 | Q19: =IF(S23="CORTE ESPECIAL ","segundos","") | S19: Pacotes | U19: Tem cnpj? | AK19: Sim Alterado | AN19: Cheque
C20: Marca | K20: Unidades | M20: =CÁLCULO!D16 -> 20000 | AN20: Boleto bancário
C21: futura | K21: Milheiros | M21: =ROUNDDOWN((M20/1000),2) -> 20
A22: Dimensões | E22: Tipo | J22: Batidas | O22: Texturas | S22: Acabamento
A23: Largura Real | C23: 10 | E23: Tafetá | J23: 25 batidas | O23: FUNDO PRESO | S23: CORTE NORMAL
A24: Larg. p/ Calc | C24: 10 | O24: Materiais | S24: Ultrassônico | AJ24: grades? - variantes - tem cnpj? | AM24: Tipo 2 de cliente
A25: Comprimento | C25: 25 | E25: Tafetá | J25: 28 batidas | O25: Nenhum | S25: NÃO | V25: Campo Obrigatório | AK25: SIM | AN25: Novo
A26: Previsão de Entrega | C26: =C11+28 -> 46009.404 | E26: 1º | I26: 2º | N26: 3º | R26: , | T26: =C11 -> 45981.404 | AK26: NÃO | AN26: Antigo
AE27: 45322
A28: GRADES | B28: NÃO | C28: Observações | K28: Variantes | O28: NÃO | Q28: Cores
A29: No. | B29: Qtd
A30: 1 | B30: 100 | K30: 1º | L30: 2º | M30: 3º | N30: 4º | O30: 5º | P30: 6º | Q30: Cor | R30: Única | T30: 1º Dens. | U30: Cor | V30: Única | W30: 2º Dens. | AJ30: Cód. Op. | AM30: Cód Fat.
A31: 02 | B31: 100 | Q31: Fd | R31: F01 | T31: 25 | U31: Fd | AK31: 1 | AN31: A | AQ31: Urdume
A32: 03 | B32: 100 | Q32: 1º | R32: F30 | T32: 20 | U32: 1º | AK32: 2 | AN32: B | AQ32: BRANCO | AS32: 1.01
A33: 04 | B33: 100 | Q33: 2º | U33: 2º | AK33: 3 | AN33: C | AQ33: BRANCO E PRETO | AS33: 1.01
A34: 05 | B34: 100 | Q34: 3º | U34: 3º | AK34: 4 | AN34: D | AQ34: CETIM - BRANCO | AS34: 1.5
Q35: 4º | U35: 4º | AK35: 5 | AN35: E | AQ35: CETIM - PRETO | AS35: 1.5
Q36: 5º | U36: 5º | AN36: F | AQ36: PRETO | AS36: 1.01
Q37: 6º | U37: 6º | AQ37: SEMICETIM - BRANCO | AS37: 1.5
Q38: 7º | U38: 7º | AJ38: Frete | AQ38: SEMICETIM - PRETO | AS38: 1.5
K39: Urdumes | Q39: Total | T39: =(SUM(T31:T38)) -> 45 | U39: =(SUM(W31:W38)) -> 0 | W39: =(SUM(W31:W38)) -> 0 | AK39: CIF | AM39: BCO | AQ39: VERMELHO | AS39: 1.2
A40: TOTAL | B40: =IF(SUM(B31:B39)>0,SUM(B31:B39),M19) -> 400 | Q40: Cor do urdume | V40: =IF(AND(U17="",M19<(T11*0.9)),"VER TABELA",IF(C23=60,1.49,1)*(IF(B40=M19,CÁLCULO!H13,"GRADE ERRADA"))*(IF(U16="",1,(IF(U15="+",(1+U16%),(1-U16%)))))*(IF(S25="sim",1.12,1)))*V41 -> #VALUE! | AK40: FOB | AM40: PTO
A41: CNPJ | Q41: BRANCO E PRETO | V41: =VLOOKUP(Q41,urdume,3) -> 1.01
AJ44: Opçoes | AM44: tipo | AN44: =LEN(E23) -> 6
A45: ---------------------------------- | F45: ---------------------------------- | R45: ---------------------------------- | AK45: Nenhum | AN45: Sarja | AO45: =LEN(AN45) -> 5 | AP45: sarja
A46: CLIENTE | F46: REVENDEDOR | L46: REVISÃO | R46: SUPERVISÃO DE VENDAS | AK46: Fundo preso | AN46: Tafetá | AO46: =LEN(AN46) -> 6 | AP46: TAFETÁ
...

Sheet Plan2
A1: banco de dados
A2: CM (COEFICIENTE POR METRAGEM) | G2: CC (COEFICIENTE POR CORTE) | L2: TABELA 3 | O2: TABELA 6 | R2: TABELA 9 | U2: TABELA 12 | X2: TABELA 15 | AA2: TABELA 18 | AD2: TABELA 21 | AG2: TABELA 24
A3: CÓD | B3: METROS | C3: TAFETÁ | D3: SARJA | E3: ALT. DEF. | I3: ETQ SCORTE | L3: CORTE NORMAL | O3: DOBRA MEIO | R3: DOBRA CANTOS | U3: CANTOSDIAGONAL | X3: DOBRA DESCENTRALIZADA | AA3: ENVELOPE | AD3: MITRA | AG3: 2 DOBRAS
B4: 300 | C4: 20.4 | D4: 22.5 | E4: 26.84 | G4: CÓD | H4: LARGURA | I4: TAFETÁ | J4: SARJA | K4: ALT. DEF. | L4: TAFETÁ | M4: SARJA | N4: ALT. DEF. | O4: TAFETÁ | P4: SARJA | Q4: ALT. DEF. | R4: TAFETÁ | S4: SARJA | T4: ALT. DEF. | U4: TAFETÁ | V4: SARJA | W4: ALT. DEF. | X4: TAFETÁ | Y4: SARJA | Z4: ALT. DEF. | AA4: TAFETÁ | AB4: SARJA | AC4: ALT. DEF. | AD4: TAFETÁ | AE4: SARJA | AF4: ALT. DEF. | AG4: TAFETÁ | AH4: SARJA | AI4: ALT. DEF.
B5: 500 | C5: 15.69 | D5: 17.29 | E5: 20.64 | H5: 10 | I5: 0.97 | J5: 0.965 | K5: 0.96 | L5: 0.823 | M5: 0.823 | N5: 0.774 | O5: 0.585 | P5: 0.585 | Q5: 0.585 | R5: 0.52 | S5: 0.52 | T5: 0.52 | U5: 0.497 | V5: 0.497 | W5: 0.497 | X5: 0.496 | Y5: 0.496 | Z5: 0.496 | AA5: 0.496 | AB5: 0.496 | AC5: 0.496 | AD5: 0.317 | AE5: 0.317 | AF5: 0.317 | AG5: 0.31 | AH5: 0.31 | AI5: 0.3
B6: 1000 | C6: 10.44 | D6: 11.48 | E6: 14.36 | H6: 12 | I6: 0.97 | J6: 0.965 | K6: 0.96 | L6: 0.823 | M6: 0.823 | N6: 0.774 | O6: 0.585 | P6: 0.585 | Q6: 0.585 | R6: 0.52 | S6: 0.52 | T6: 0.52 | U6: 0.497 | V6: 0.497 | W6: 0.497 | X6: 0.496 | Y6: 0.496 | Z6: 0.496 | AA6: 0.496 | AB6: 0.496 | AC6: 0.496 | AD6: 0.317 | AE6: 0.317 | AF6: 0.317 | AG6: 0.31 | AH6: 0.31 | AI6: 0.3
B7: 2500 | C7: 10.11 | D7: 11.12 | E7: 13.21 | H7: 15 | I7: 0.97 | J7: 0.965 | K7: 0.96 | L7: 0.823 | M7: 0.823 | N7: 0.774 | O7: 0.666 | P7: 0.666 | Q7: 0.666 | R7: 0.64 | S7: 0.63 | T7: 0.62 | U7: 0.598 | V7: 0.598 | W7: 0.598 | X7: 0.597 | Y7: 0.597 | Z7: 0.597 | AA7: 0.597 | AB7: 0.597 | AC7: 0.597 | AD7: 0.4395 | AE7: 0.4395 | AF7: 0.4395 | AG7: 0.41 | AH7: 0.41 | AI7: 0.4
B8: 5000 | C8: 9.35 | D8: 10.29 | E8: 12.58 | H8: 18 | I8: 0.97 | J8: 0.965 | K8: 0.96 | L8: 0.823 | M8: 0.823 | N8: 0.774 | O8: 0.716 | P8: 0.716 | Q8: 0.716 | R8: 0.69 | S8: 0.68 | T8: 0.67 | U8: 0.655 | V8: 0.655 | W8: 0.655 | X8: 0.64 | Y8: 0.64 | Z8: 0.64 | AA8: 0.64 | AB8: 0.64 | AC8: 0.64 | AD8: 0.515 | AE8: 0.515 | AF8: 0.4935 | AG8: 0.41 | AH8: 0.41 | AI8: 0.4
B9: 10000 | C9: 8.39 | D9: 9.22 | E9: 11.89 | H9: 20 | I9: 0.97 | J9: 0.965 | K9: 0.96 | L9: 0.823 | M9: 0.823 | N9: 0.774 | O9: 0.73 | P9: 0.73 | Q9: 0.73 | R9: 0.72 | S9: 0.71 | T9: 0.7 | U9: 0.66 | V9: 0.66 | W9: 0.66 | X9: 0.64 | Y9: 0.64 | Z9: 0.64 | AA9: 0.64 | AB9: 0.64 | AC9: 0.64 | AD9: 0.5585 | AE9: 0.5585 | AF9: 0.529 | AG9: 0.41 | AH9: 0.41 | AI9: 0.4
B10: 15000 | C10: 8.04 | D10: 8.84 | E10: 11.35 | H10: 21 | I10: 0.97 | J10: 0.965 | K10: 0.96 | L10: 0.823 | M10: 0.823 | N10: 0.774 | O10: 0.73 | P10: 0.73 | Q10: 0.73 | R10: 0.72 | S10: 0.71 | T10: 0.68 | U10: 0.655 | V10: 0.655 | W10: 0.655 | X10: 0.64 | Y10: 0.64 | Z10: 0.64 | AA10: 0.64 | AB10: 0.64 | AC10: 0.64 | AD10: 0.5585 | AE10: 0.5585 | AF10: 0.529 | AG10: 0.4 | AH10: 0.4 | AI10: 0.39
B11: 30000 | C11: 7.72 | D11: 8.48 | E11: 10.89 | H11: 24 | I11: 0.97 | J11: 0.965 | K11: 0.96 | L11: 0.823 | M11: 0.823 | N11: 0.774 | O11: 0.822 | P11: 0.822 | Q11: 0.772 | R11: 0.81 | S11: 0.8 | T11: 0.75 | U11: 0.655 | V11: 0.655 | W11: 0.655 | X11: 0.64 | Y11: 0.64 | Z11: 0.64 | AA11: 0.64 | AB11: 0.64 | AC11: 0.64 | AD11: 0.62 | AE11: 0.62 | AF11: 0.62 | AG11: 0.51 | AH11: 0.51 | AI11: 0.5
H12: 28 | I12: 0.97 | J12: 0.965 | K12: 0.96 | L12: 0.823 | M12: 0.823 | N12: 0.774 | O12: 0.822 | P12: 0.822 | Q12: 0.774 | R12: 0.81 | S12: 0.8 | T12: 0.75 | U12: 0.73 | V12: 0.73 | W12: 0.7 | X12: 0.72 | Y12: 0.72 | Z12: 0.69 | AA12: 0.72 | AB12: 0.72 | AC12: 0.69 | AD12: 0.68 | AE12: 0.68 | AF12: 0.67 | AG12: 0.51 | AH12: 0.51 | AI12: 0.5
A13: CODIFICAÇÃO PARA CM | H13: 30 | I13: 0.97 | J13: 0.965 | K13: 0.96 | L13: 0.823 | M13: 0.823 | N13: 0.774 | O13: 0.822 | P13: 0.822 | Q13: 0.774 | R13: 0.81 | S13: 0.8 | T13: 0.75 | U13: 0.73 | V13: 0.73 | W13: 0.7 | X13: 0.72 | Y13: 0.72 | Z13: 0.69 | AA13: 0.72 | AB13: 0.72 | AC13: 0.69 | AD13: 0.68 | AE13: 0.68 | AF13: 0.67 | AG13: 0.51 | AH13: 0.51 | AI13: 0.5
A14: COD TIPO | B14: SOMA CT | C14: TOTAL | E14: GOMA | H14: 33 | I14: 0.97 | J14: 0.965 | K14: 0.96 | L14: 0.823 | M14: 0.823 | N14: 0.774 | O14: 0.822 | P14: 0.822 | Q14: 0.774 | R14: 0.81 | S14: 0.8 | T14: 0.75 | U14: 0.73 | V14: 0.73 | W14: 0.7 | X14: 0.72 | Y14: 0.72 | Z14: 0.69 | AA14: 0.72 | AB14: 0.72 | AC14: 0.69 | AD14: 0.68 | AE14: 0.68 | AF14: 0.67 | AG14: 0.51 | AH14: 0.51 | AI14: 0.5
A15: =LEN(CÁLCULO!D5) -> 6 | B15: =VLOOKUP(C15,tab_cortes,2,FALSE) -> 3 | C15: =LEN(CÁLCULO!D3) -> 13 | D15: =LEN(CÁLCULO!E3) -> 0 | E15: {=VLOOKUP(Tabela!AL56,Tabela!AL58:AM64,2,Tabela!AL58:AL64)} -> 2 | H15: 40 | I15: 0.97 | J15: 0.965 | K15: 0.96 | L15: 0.823 | M15: 0.823 | N15: 0.774 | O15: 0.822 | P15: 0.822 | Q15: 0.774 | R15: 0.81 | S15: 0.8 | T15: 0.75 | U15: 0.71 | V15: 0.71 | W15: 0.7 | X15: 0.7 | Y15: 0.7 | Z15: 0.69 | AA15: 0.7 | AB15: 0.7 | AC15: 0.69 | AD15: 0.68 | AE15: 0.68 | AF15: 0.67 | AG15: 0.51 | AH15: 0.51 | AI15: 0.5
A16: CC | B16: =VLOOKUP(24,tabela_fator,B15+VLOOKUP(A15,B19:C21,2,FALSE),FALSE) -> 0.823 | H16: 50 | I16: 0.97 | J16: 0.965 | K16: 0.96 | L16: 0.823 | M16: 0.823 | N16: 0.774 | O16: 0.822 | P16: 0.822 | Q16: 0.774 | R16: 0.81 | S16: 0.8 | T16: 0.75 | U16: 0.71 | V16: 0.71 | W16: 0.7 | X16: 0.7 | Y16: 0.7 | Z16: 0.69 | AA16: 0.7 | AB16: 0.7 | AC16: 0.69 | AD16: 0.68 | AE16: 0.68 | AF16: 0.67 | AG16: 0.51 | AH16: 0.51 | AI16: 0.5
A17: =LEN(CÁLCULO!D7) -> 6 | B17: =VLOOKUP(Plan2!C15,tab_cortes,2,FALSE) -> 3 | C17: =LEN(CÁLCULO!D3) -> 13 | H17: 67 | I17: 0.97 | J17: 0.965 | K17: 0.96 | L17: 0.823 | M17: 0.823 | N17: 0.774 | O17: 0.822 | P17: 0.822 | Q17: 0.774 | R17: 0.81 | S17: 0.8 | T17: 0.75 | U17: 0.71 | V17: 0.71 | W17: 0.7 | X17: 0.7 | Y17: 0.7 | Z17: 0.69 | AA17: 0.7 | AB17: 0.7 | AC17: 0.69 | AD17: 0.68 | AE17: 0.68 | AF17: 0.67 | AG17: 0.51 | AH17: 0.51 | AI17: 0.5
H18: 100 | I18: 0.97 | J18: 0.965 | K18: 0.96 | L18: 0.823 | M18: 0.823 | N18: 0.774 | O18: 0.822 | P18: 0.822 | Q18: 0.774 | R18: 0.81 | S18: 0.8 | T18: 0.75 | U18: 0.71 | V18: 0.71 | W18: 0.7 | X18: 0.7 | Y18: 0.7 | Z18: 0.69 | AA18: 0.7 | AB18: 0.7 | AC18: 0.69 | AD18: 0.68 | AE18: 0.68 | AF18: 0.67 | AG18: 0.51 | AH18: 0.51 | AI18: 0.5
A19: SARJA | B19: =LEN(A19) -> 5 | C19: 3
A20: TAFETÁ | B20: =LEN(A20) -> 6 | C20: 2 | O20: {=VLOOKUP(Plan2!O21,Plan2!O24:P28,2,Plan2!O24:O28)} -> 1.2723
A21: ALTA DEFINIÇÃO | B21: =LEN(A21) -> 14 | C21: 4 | L21: {=IF(CÁLCULO!E7="",1,VLOOKUP(CÁLCULO!E7,Plan2!L24:M27,2,Plan2!L24:L27))} -> 1 | O21: =CÁLCULO!E5 -> 1
D22: GOMA | L22: PACOTES | O22: DESCONTO | R22: A | S22: B | T22: C | X22: D | Y22: E | Z22: MEIO CORTE
A23: FITAS | D23: LARGURA | E23: F | F23: G | G23: colafria | H23: termo | I23: fino | J23: grosso | L23: QUANT. | M23: % | O23: COD | P23: TABELA | Z23: LARGURA | AA23: A
A24: 10 | B24: 78.2 | D24: 10 | E24: 0.029 | F24: 0.052 | G24: 0.2 | H24: 0.189 | I24: 0.087 | J24: 0.141 | L24: 100 | M24: 1.22 | O24: =CÁLCULO!J48 -> 1 | P24: 1.2723 | Z24: 10 | AA24: 0.2
A25: 12 | B25: 67 | D25: 12 | E25: 0.035 | F25: 0.062 | G25: 0.2 | H25: 0.226 | I25: 0.087 | J25: 0.141 | L25: 200 | M25: 1.17 | O25: =CÁLCULO!J49 -> 2 | P25: 1.374 | Z25: 12 | AA25: 0.25
A26: 15 | B26: 61 | D26: 15 | E26: 0.043 | F26: 0.078 | G26: 0.25 | H26: 0.247 | I26: 0.13 | J26: 0.176 | L26: 500 | M26: 1.12 | O26: =CÁLCULO!J50 -> 3 | P26: 1.484 | Z26: 15 | AA26: 0.25
A27: 18 | B27: 47.6 | D27: 18 | E27: 0.051 | F27: 0.089 | G27: 0.3 | H27: 0.305 | I27: 0.174 | J27: 0.212 | L27: 1000 | M27: 1.07 | O27: =CÁLCULO!J51 -> 4 | P27: 1.6027 | Z27: 18 | AA27: 0.3
A28: 20 | B28: 47.6 | D28: 20 | E28: 0.058 | F28: 0.1 | G28: 0.3 | H28: 0.305 | I28: 0.174 | J28: 0.212 | O28: =CÁLCULO!J52 -> 5 | P28: 1.7308 | Z28: 20 | AA28: 0.3
A29: 21 | B29: 45.4 | D29: 21 | E29: 0.065 | F29: 0.107 | G29: 0.3 | H29: 0.353 | I29: 0.216 | J29: 0.247 | Z29: 21 | AA29: 0.3
A30: 24 | B30: 43.4 | D30: 24 | E30: 0.073 | F30: 0.11 | G30: 0.4 | H30: 0.353 | I30: 0.216 | J30: 0.247 | Z30: 24 | AA30: 0.4
A31: 28 | B31: 38.3 | D31: 28 | E31: 0.085 | F31: 0.128 | G31: 0.45 | H31: 0.412 | I31: 0.246 | J31: 0.282 | L31: ETAPAS DE CALCULO | Z31: 28 | AA31: 0.45
A32: 30 | B32: 33.2 | D32: 30 | E32: 0.1 | F32: 0.136 | G32: 0.5 | H32: 0.482 | I32: 0.288 | J32: 0.33 | L32: SG | M32: CM | N32: FITAS | O32: CC | P32: =Tabela!O25 -> Nenhum | Q32: MEIO CORTE | Z32: 30 | AA32: 0.5
A33: 33 | B33: 33.2 | D33: 33 | E33: 0.1 | F33: 0.136 | G33: 0.5 | H33: 0.482 | I33: 0.288 | J33: 0.33 | L33: =CÁLCULO!C5 -> 45 | M33: =VLOOKUP(CÁLCULO!B3,tab_metros,VLOOKUP(A15,B19:C21,2,FALSE),FALSE) -> 15.69 | N33: =VLOOKUP(CÁLCULO!B5,A24:B38,2,A24:A38) -> 78.2 | O33: =VLOOKUP(CÁLCULO!B5,Plan2!H5:AI18,(VLOOKUP(Plan2!A15,Plan2!B19:C21,2)+Plan2!B15)) -> 0.823 | P33: =IF(Tabela!O25="NENHUM",0,VLOOKUP(Tabela!C24,Plan2!D24:J38,Plan2!E15,Plan2!D24:D38)) -> 0 | Z33: 33 | AA33: 0.5
A34: 40 | B34: 28.1 | D34: 40 | E34: 0.116 | F34: 0.176 | G34: 0.55 | H34: 0.541 | I34: 0.348 | J34: 0.398 | L34: SG | M34: CM | N34: FITAS | O34: CC | P34: GOMA | Q34: MEIO CORTE | Z34: 40 | AA34: 0.55
A35: 50 | B35: 23 | D35: 50 | E35: 0.145 | F35: 0.22 | G35: 0.7 | H35: 0.67 | I35: 0.432 | J35: 0.497 | L35: =CÁLCULO!C7 -> 0 | M35: =VLOOKUP(CÁLCULO!B3,B4:E11,VLOOKUP(A17,B19:C21,2,FALSE),FALSE) -> 15.69 | N35: =VLOOKUP(CÁLCULO!B5,A24:B38,2,A24:A38) -> 78.2 | O35: =VLOOKUP(CÁLCULO!B5,Plan2!H5:AL18,(VLOOKUP(Plan2!A17,Plan2!B19:C21,2)+Plan2!B15)) -> 0.823 | P35: =IF(Tabela!O25="NENHUM",0,VLOOKUP(Tabela!C24,Plan2!D24:J38,Plan2!E15,Plan2!D24:D38)) -> 0 | Z35: 50 | AA35: 0.7
A36: 67 | B36: 13.5 | D36: 67 | E36: 0.194 | F36: 0.295 | G36: 0.95 | H36: 0.941 | I36: 0.588 | J36: 0.675 | Z36: 67 | AA36: 0.85
A37: 100 | B37: 11.5 | D37: 100 | E37: 0.29 | F37: 0.44 | G37: 1.4 | H37: 1.339 | I37: 0.882 | J37: 1.101 | Z37: 100 | AA37: 0.95
A38: 200 | B38: 5.9 | D38: 200 | E38: 0.5 | F38: 0.6 | G38: 2.8 | H38: 2.6 | I38: 1.6 | J38: 2
M39: =A17 -> 6
M40: =VLOOKUP(CÁLCULO!B3,B4:E11,1,FALSE) -> 500 | O40: =VLOOKUP(var_largura,tabela_fator,VLOOKUP(Plan2!A15,Plan2!B19:C21,2)) -> 0.97
...

Sheet CÁLCULO
A1: TABELA PARA CÁLCULOS DE ETIQUETAS
A2: QUANT. DE METROS | B2: TABELA | C2: COR URDUME | D2: CORTE | E2: TIPO DE GOMA | H2: CONVERSOR UNIDADE X METROS
A3: =Tabela!M19 -> 500 | B3: =Tabela!T11 -> 500 | C3: =Tabela!Q41 -> BRANCO E PRETO | D3: =Tabela!S23 -> CORTE NORMAL | H3: UNIDADE
A4: COMPRIMENTO(mm)1 | B4: LARGURA(mm)1 | C4: SM1 | E4: TABELA
A5: =IF(Tabela!E23="Dupla densidade",Tabela!C25/2,Tabela!C25) -> 25 | B5: =Tabela!C24 -> 10 | C5: =Tabela!T39 -> 45 | D5: {=VLOOKUP(Tabela!AN44,Tabela!AO45:AP49,2,Tabela!AO45:AO49)} -> TAFETÁ | E5: {=Tabela!N11} -> 1 | H5: METROS
A6: COMPRIMENTO(mm)2 | B6: LARGURA(mm)2 | C6: SM2 | D6: TIPO 2 | E6: UNID. POR PACOTE | H6: {=+ROUND((A9/1000)*H4,0)} -> 0
A7: {=IF(Tabela!E23="Dupla densidade",Tabela!C25/2,0)} -> 0 | B7: =B5 -> 10 | C7: {=IF(Tabela!E23="Dupla densidade",Tabela!U39,0)} -> 0 | D7: =Tabela!E25 -> Tafetá | E7: {=IF(Tabela!S20="","",Tabela!S20)}
A8: COMPRIMENTO TOTAL | D8: TIPO REAL(ORÇAMENTO)
A9: {=A5+A7} -> 25
A11: VALORES | E11: MARCA
A12: VALOR DO MILHEIRO 1 | B12: VALOR DO MILHEIRO 2 | C12: VALOR DO MILHEIRO TOTAL | D12: VALOR DO METRO | H12: VALOR TOTAL
A13: =Tabela!E15 -> 14.081016 | B13: =IF(Plan2!L35=0,0,ROUND(Plan2!L35*Plan2!M35/Plan2!N35/Plan2!O35*Tabela!AM102,5)) -> 0 | C13: =((ROUND(((((((D25)+B16)+C16)*A5)/CC)*Tabela!AJ102)+(IF(Plan2!L35=0,0,ROUND(Plan2!L35*Plan2!M35/Plan2!N35/Plan2!O35*Tabela!AM102,5))),5)+(Tabela!AS51))*(Plan2!O20))*(Plan2!L21) -> 12.562067 | D13: =ROUND((C13/A9),5) -> 0.50248 | H13: =(D13)*(A3) -> 251.24
E14: REPRESENTANTE | H14: 7352911
A15: VALOR DA UNIDADE | B15: VALOR GOMA P/METRO | C15: VALOR MEIO- CORTE | D15: QUANTIDADE DE ETIQUETAS
A16: {=ROUND(C13/1000,5)} -> 0.01256 | B16: =Plan2!P33 -> 0 | C16: =IF(D3="MEIO CORTE",Plan2!Q33,0) -> 0 | D16: =ROUND(A3/(A9/1000),0) -> 20000
C25: algumacoisa | D25: =Plan2!L33*Plan2!M33/Plan2!N33/A5 -> 0.3611509
C26: CC | D26: =Plan2!O33 -> 0.823
A38: TIPO | B38: LARGURAS | C38: METROS | D38: CORTES | E38: CARAC | F38: TAB | G38: URDUMES
D39: GALAO | E39: =LEN(D39) -> 5 | F39: 0 | G39: BRANCO | I39: GOMAS
C40: 300 | D40: 2DOBRAS | E40: =LEN(D40) -> 7 | F40: 24 | G40: PRETO
A41: TAFETÁ | B41: 10 | C41: 500 | D41: ENVELOPE | E41: =LEN(D41) -> 8 | F41: 15 | G41: VERMELHO | I41: F | J41: =LEN(I41) -> 1 | K41: 2
A42: SARJA | B42: 12 | C42: 1000 | D42: SAQUINHO | E42: =LEN(D42) -> 9 | F42: 3 | I42: M | J42: =LEN(I42) -> 2 | K42: 3
A43: ALTA DEFINIÇÃO | B43: 15 | C43: 2500 | D43: DOBRA MEIO | E43: =LEN(D43) -> 11 | F43: 6 | G43: pacotes | I43: G | J43: =LEN(I43) -> 3 | K43: 4
B44: 18 | C44: 5000 | D44: ETQ S/ CORTE | E44: =LEN(D44) -> 12 | F44: 0 | G44: 100
B45: 20 | C45: 10000 | D45: CORTE NORMAL | E45: =LEN(D45) -> 13 | F45: 3 | G45: 200
B46: 21 | C46: 15000 | D46: DOBRA CANTOS | E46: =LEN(D46) -> 14 | F46: 9 | G46: 500 | I46: DESCONTOS
B47: 24 | C47: 30000 | D47: CORTE ESPECIAL | E47: =LEN(D47) -> 15 | F47: 9
B48: 28 | D48: DOBRA MEIO CLIPS | E48: =LEN(D48) -> 16 | F48: 15 | I48: 1 | J48: =LEN(I48) -> 1 | K48: 2
B49: 30 | D49: MITRA | E49: =LEN(D49) -> 17 | F49: 21 | I49: 2 | J49: =LEN(I49) -> 2 | K49: 3
B50: 33 | D50: CANTOS DIAGONAL | E50: =LEN(D50) -> 18 | F50: 12 | I50: 3 | J50: =LEN(I50) -> 3 | K50: 4
B51: 40 | D51: 4CANTOS | E51: =LEN(D51) -> 19 | F51: 24 | I51: 4 | J51: =LEN(I51) -> 4 | K51: 5
B52: 50 | D52: DOBRA DESCENTRALIZADA | E52: =LEN(D52) -> 21 | F52: 15 | I52: 5 | J52: =LEN(I52) -> 5 | K52: 6
B53: 67 | E53: =LEN(D53) -> 0
E54: =LEN(D54) -> 0
E55: =LEN(D55) -> 0
E56: =LEN(D56) -> 0
E57: =LEN(D57) -> 0
E58: =LEN(D58) -> 0
E59: =LEN(D59) -> 0
E60: =LEN(D60) -> 0

Sheet Plan1
